2025-02-26 22:12:57,204 INFO    StreamThr :13635 [internal.py:wandb_internal():86] W&B internal server running at pid: 13635, started at: 2025-02-26 22:12:57.203449
2025-02-26 22:12:57,204 DEBUG   HandlerThread:13635 [handler.py:handle_request():146] handle_request: status
2025-02-26 22:12:57,208 INFO    WriterThread:13635 [datastore.py:open_for_write():87] open: /Users/cpconnor/CascadeProjects/multi-platform-content-generator/wandb/run-20250226_221257-krq6o5ea/run-krq6o5ea.wandb
2025-02-26 22:12:57,208 DEBUG   SenderThread:13635 [sender.py:send():379] send: header
2025-02-26 22:12:57,208 DEBUG   SenderThread:13635 [sender.py:send():379] send: run
2025-02-26 22:12:57,212 INFO    SenderThread:13635 [sender.py:_setup_resume():749] checking resume status for None/pete-connor-cx-ai-expert/krq6o5ea
2025-02-26 22:12:57,420 ERROR   SenderThread:13635 [internal_api.py:execute():373] 401 response executing GraphQL.
2025-02-26 22:12:57,420 ERROR   SenderThread:13635 [internal_api.py:execute():374] {"errors":[{"message":"user is not logged in","path":["upsertBucket"],"extensions":{"code":"PERMISSION_ERROR"}}],"data":{"upsertBucket":null}}
2025-02-26 22:12:57,420 ERROR   SenderThread:13635 [sender.py:send_run():971] The API key you provided is either invalid or missing.  If the `WANDB_API_KEY` environment variable is set, make sure it is correct. Otherwise, to resolve this issue, you may try running the 'wandb login --relogin' command. If you are using a local server, make sure that you're using the correct hostname. If you're not sure, you can try logging in again using the 'wandb login --relogin --host [hostname]' command.(Error 401: Unauthorized)
Traceback (most recent call last):
  File "/Users/cpconnor/CascadeProjects/multi-platform-content-generator/venv/lib/python3.13/site-packages/wandb/sdk/lib/retry.py", line 131, in __call__
    result = self._call_fn(*args, **kwargs)
  File "/Users/cpconnor/CascadeProjects/multi-platform-content-generator/venv/lib/python3.13/site-packages/wandb/sdk/internal/internal_api.py", line 369, in execute
    return self.client.execute(*args, **kwargs)  # type: ignore
           ~~~~~~~~~~~~~~~~~~~^^^^^^^^^^^^^^^^^
  File "/Users/cpconnor/CascadeProjects/multi-platform-content-generator/venv/lib/python3.13/site-packages/wandb/vendor/gql-0.2.0/wandb_gql/client.py", line 52, in execute
    result = self._get_result(document, *args, **kwargs)
  File "/Users/cpconnor/CascadeProjects/multi-platform-content-generator/venv/lib/python3.13/site-packages/wandb/vendor/gql-0.2.0/wandb_gql/client.py", line 60, in _get_result
    return self.transport.execute(document, *args, **kwargs)
           ~~~~~~~~~~~~~~~~~~~~~~^^^^^^^^^^^^^^^^^^^^^^^^^^^
  File "/Users/cpconnor/CascadeProjects/multi-platform-content-generator/venv/lib/python3.13/site-packages/wandb/sdk/lib/gql_request.py", line 59, in execute
    request.raise_for_status()
    ~~~~~~~~~~~~~~~~~~~~~~~~^^
  File "/Users/cpconnor/CascadeProjects/multi-platform-content-generator/venv/lib/python3.13/site-packages/requests/models.py", line 1024, in raise_for_status
    raise HTTPError(http_error_msg, response=self)
requests.exceptions.HTTPError: 401 Client Error: Unauthorized for url: https://api.wandb.ai/graphql

During handling of the above exception, another exception occurred:

Traceback (most recent call last):
  File "/Users/cpconnor/CascadeProjects/multi-platform-content-generator/venv/lib/python3.13/site-packages/wandb/sdk/internal/sender.py", line 969, in send_run
    server_run = self._init_run(run, config_value_dict)
  File "/Users/cpconnor/CascadeProjects/multi-platform-content-generator/venv/lib/python3.13/site-packages/wandb/sdk/internal/sender.py", line 1014, in _init_run
    server_run, inserted, server_messages = self._api.upsert_run(
                                            ~~~~~~~~~~~~~~~~~~~~^
        name=run.run_id,
        ^^^^^^^^^^^^^^^^
    ...<12 lines>...
        commit=run.git.commit or None,
        ^^^^^^^^^^^^^^^^^^^^^^^^^^^^^^
    )
    ^
  File "/Users/cpconnor/CascadeProjects/multi-platform-content-generator/venv/lib/python3.13/site-packages/wandb/apis/normalize.py", line 73, in wrapper
    raise err
  File "/Users/cpconnor/CascadeProjects/multi-platform-content-generator/venv/lib/python3.13/site-packages/wandb/apis/normalize.py", line 41, in wrapper
    return func(*args, **kwargs)
  File "/Users/cpconnor/CascadeProjects/multi-platform-content-generator/venv/lib/python3.13/site-packages/wandb/sdk/internal/internal_api.py", line 2217, in upsert_run
    response = self.gql(
        mutation,
    ...<2 lines>...
        **kwargs,
    )
  File "/Users/cpconnor/CascadeProjects/multi-platform-content-generator/venv/lib/python3.13/site-packages/wandb/sdk/internal/internal_api.py", line 341, in gql
    ret = self._retry_gql(
        *args,
        retry_cancel_event=self.context.cancel_event,
        **kwargs,
    )
  File "/Users/cpconnor/CascadeProjects/multi-platform-content-generator/venv/lib/python3.13/site-packages/wandb/sdk/lib/retry.py", line 147, in __call__
    retry_timedelta_triggered = check_retry_fn(e)
  File "/Users/cpconnor/CascadeProjects/multi-platform-content-generator/venv/lib/python3.13/site-packages/wandb/util.py", line 968, in check_retry_fn
    return fallback_retry_fn(e)
  File "/Users/cpconnor/CascadeProjects/multi-platform-content-generator/venv/lib/python3.13/site-packages/wandb/util.py", line 899, in no_retry_auth
    raise AuthenticationError(
    ...<6 lines>...
    )
wandb.errors.AuthenticationError: The API key you provided is either invalid or missing.  If the `WANDB_API_KEY` environment variable is set, make sure it is correct. Otherwise, to resolve this issue, you may try running the 'wandb login --relogin' command. If you are using a local server, make sure that you're using the correct hostname. If you're not sure, you can try logging in again using the 'wandb login --relogin --host [hostname]' command.(Error 401: Unauthorized)
2025-02-26 22:13:00,161 INFO    StreamThr :13635 [internal.py:wandb_internal():86] W&B internal server running at pid: 13635, started at: 2025-02-26 22:13:00.161340
2025-02-26 22:13:00,162 DEBUG   HandlerThread:13635 [handler.py:handle_request():146] handle_request: status
2025-02-26 22:13:00,162 INFO    WriterThread:13635 [datastore.py:open_for_write():87] open: /Users/cpconnor/CascadeProjects/multi-platform-content-generator/wandb/run-20250226_221300-qdxhb707/run-qdxhb707.wandb
2025-02-26 22:13:00,163 DEBUG   SenderThread:13635 [sender.py:send():379] send: header
2025-02-26 22:13:00,163 DEBUG   SenderThread:13635 [sender.py:send():379] send: run
2025-02-26 22:13:00,395 ERROR   SenderThread:13635 [internal_api.py:execute():373] 401 response executing GraphQL.
2025-02-26 22:13:00,395 ERROR   SenderThread:13635 [internal_api.py:execute():374] {"errors":[{"message":"user is not logged in","path":["upsertBucket"],"extensions":{"code":"PERMISSION_ERROR"}}],"data":{"upsertBucket":null}}
2025-02-26 22:13:00,395 ERROR   SenderThread:13635 [sender.py:send_run():971] [Errno 32] Broken pipe
Traceback (most recent call last):
  File "/Users/cpconnor/CascadeProjects/multi-platform-content-generator/venv/lib/python3.13/site-packages/wandb/sdk/internal/internal_api.py", line 369, in execute
    return self.client.execute(*args, **kwargs)  # type: ignore
           ~~~~~~~~~~~~~~~~~~~^^^^^^^^^^^^^^^^^
  File "/Users/cpconnor/CascadeProjects/multi-platform-content-generator/venv/lib/python3.13/site-packages/wandb/vendor/gql-0.2.0/wandb_gql/client.py", line 52, in execute
    result = self._get_result(document, *args, **kwargs)
  File "/Users/cpconnor/CascadeProjects/multi-platform-content-generator/venv/lib/python3.13/site-packages/wandb/vendor/gql-0.2.0/wandb_gql/client.py", line 60, in _get_result
    return self.transport.execute(document, *args, **kwargs)
           ~~~~~~~~~~~~~~~~~~~~~~^^^^^^^^^^^^^^^^^^^^^^^^^^^
  File "/Users/cpconnor/CascadeProjects/multi-platform-content-generator/venv/lib/python3.13/site-packages/wandb/sdk/lib/gql_request.py", line 59, in execute
    request.raise_for_status()
    ~~~~~~~~~~~~~~~~~~~~~~~~^^
  File "/Users/cpconnor/CascadeProjects/multi-platform-content-generator/venv/lib/python3.13/site-packages/requests/models.py", line 1024, in raise_for_status
    raise HTTPError(http_error_msg, response=self)
requests.exceptions.HTTPError: 401 Client Error: Unauthorized for url: https://api.wandb.ai/graphql

During handling of the above exception, another exception occurred:

Traceback (most recent call last):
  File "/Users/cpconnor/CascadeProjects/multi-platform-content-generator/venv/lib/python3.13/site-packages/wandb/apis/normalize.py", line 41, in wrapper
    return func(*args, **kwargs)
  File "/Users/cpconnor/CascadeProjects/multi-platform-content-generator/venv/lib/python3.13/site-packages/wandb/sdk/internal/internal_api.py", line 2217, in upsert_run
    response = self.gql(
        mutation,
    ...<2 lines>...
        **kwargs,
    )
  File "/Users/cpconnor/CascadeProjects/multi-platform-content-generator/venv/lib/python3.13/site-packages/wandb/sdk/internal/internal_api.py", line 341, in gql
    ret = self._retry_gql(
        *args,
        retry_cancel_event=self.context.cancel_event,
        **kwargs,
    )
  File "/Users/cpconnor/CascadeProjects/multi-platform-content-generator/venv/lib/python3.13/site-packages/wandb/sdk/lib/retry.py", line 131, in __call__
    result = self._call_fn(*args, **kwargs)
  File "/Users/cpconnor/CascadeProjects/multi-platform-content-generator/venv/lib/python3.13/site-packages/wandb/sdk/internal/internal_api.py", line 376, in execute
    wandb.termerror(f"Error while calling W&B API: {error} ({response})")
    ~~~~~~~~~~~~~~~^^^^^^^^^^^^^^^^^^^^^^^^^^^^^^^^^^^^^^^^^^^^^^^^^^^^^^
  File "/Users/cpconnor/CascadeProjects/multi-platform-content-generator/venv/lib/python3.13/site-packages/wandb/errors/term.py", line 61, in termerror
    _log(
    ~~~~^
        string=string,
        ^^^^^^^^^^^^^^
    ...<3 lines>...
        **kwargs,
        ^^^^^^^^^
    )
    ^
  File "/Users/cpconnor/CascadeProjects/multi-platform-content-generator/venv/lib/python3.13/site-packages/wandb/errors/term.py", line 95, in _log
    click.echo(line, file=sys.stderr, nl=newline)
    ~~~~~~~~~~^^^^^^^^^^^^^^^^^^^^^^^^^^^^^^^^^^^
  File "/Users/cpconnor/CascadeProjects/multi-platform-content-generator/venv/lib/python3.13/site-packages/click/utils.py", line 318, in echo
    file.write(out)  # type: ignore
    ~~~~~~~~~~^^^^^
BrokenPipeError: [Errno 32] Broken pipe

During handling of the above exception, another exception occurred:

Traceback (most recent call last):
  File "/Users/cpconnor/CascadeProjects/multi-platform-content-generator/venv/lib/python3.13/site-packages/wandb/sdk/internal/sender.py", line 969, in send_run
    server_run = self._init_run(run, config_value_dict)
  File "/Users/cpconnor/CascadeProjects/multi-platform-content-generator/venv/lib/python3.13/site-packages/wandb/sdk/internal/sender.py", line 1014, in _init_run
    server_run, inserted, server_messages = self._api.upsert_run(
                                            ~~~~~~~~~~~~~~~~~~~~^
        name=run.run_id,
        ^^^^^^^^^^^^^^^^
    ...<12 lines>...
        commit=run.git.commit or None,
        ^^^^^^^^^^^^^^^^^^^^^^^^^^^^^^
    )
    ^
  File "/Users/cpconnor/CascadeProjects/multi-platform-content-generator/venv/lib/python3.13/site-packages/wandb/apis/normalize.py", line 87, in wrapper
    raise CommError(message, err).with_traceback(sys.exc_info()[2])
  File "/Users/cpconnor/CascadeProjects/multi-platform-content-generator/venv/lib/python3.13/site-packages/wandb/apis/normalize.py", line 41, in wrapper
    return func(*args, **kwargs)
  File "/Users/cpconnor/CascadeProjects/multi-platform-content-generator/venv/lib/python3.13/site-packages/wandb/sdk/internal/internal_api.py", line 2217, in upsert_run
    response = self.gql(
        mutation,
    ...<2 lines>...
        **kwargs,
    )
  File "/Users/cpconnor/CascadeProjects/multi-platform-content-generator/venv/lib/python3.13/site-packages/wandb/sdk/internal/internal_api.py", line 341, in gql
    ret = self._retry_gql(
        *args,
        retry_cancel_event=self.context.cancel_event,
        **kwargs,
    )
  File "/Users/cpconnor/CascadeProjects/multi-platform-content-generator/venv/lib/python3.13/site-packages/wandb/sdk/lib/retry.py", line 131, in __call__
    result = self._call_fn(*args, **kwargs)
  File "/Users/cpconnor/CascadeProjects/multi-platform-content-generator/venv/lib/python3.13/site-packages/wandb/sdk/internal/internal_api.py", line 376, in execute
    wandb.termerror(f"Error while calling W&B API: {error} ({response})")
    ~~~~~~~~~~~~~~~^^^^^^^^^^^^^^^^^^^^^^^^^^^^^^^^^^^^^^^^^^^^^^^^^^^^^^
  File "/Users/cpconnor/CascadeProjects/multi-platform-content-generator/venv/lib/python3.13/site-packages/wandb/errors/term.py", line 61, in termerror
    _log(
    ~~~~^
        string=string,
        ^^^^^^^^^^^^^^
    ...<3 lines>...
        **kwargs,
        ^^^^^^^^^
    )
    ^
  File "/Users/cpconnor/CascadeProjects/multi-platform-content-generator/venv/lib/python3.13/site-packages/wandb/errors/term.py", line 95, in _log
    click.echo(line, file=sys.stderr, nl=newline)
    ~~~~~~~~~~^^^^^^^^^^^^^^^^^^^^^^^^^^^^^^^^^^^
  File "/Users/cpconnor/CascadeProjects/multi-platform-content-generator/venv/lib/python3.13/site-packages/click/utils.py", line 318, in echo
    file.write(out)  # type: ignore
    ~~~~~~~~~~^^^^^
wandb.errors.CommError: [Errno 32] Broken pipe
2025-02-26 22:13:02,448 DEBUG   HandlerThread:13635 [handler.py:handle_request():146] handle_request: status_report
2025-02-26 22:13:05,179 DEBUG   HandlerThread:13635 [handler.py:handle_request():146] handle_request: keepalive
2025-02-26 22:13:05,409 DEBUG   HandlerThread:13635 [handler.py:handle_request():146] handle_request: status_report
2025-02-26 22:13:07,460 DEBUG   HandlerThread:13635 [handler.py:handle_request():146] handle_request: status_report
2025-02-26 22:13:10,195 DEBUG   HandlerThread:13635 [handler.py:handle_request():146] handle_request: keepalive
2025-02-26 22:13:10,428 DEBUG   HandlerThread:13635 [handler.py:handle_request():146] handle_request: status_report
2025-02-26 22:13:12,474 DEBUG   HandlerThread:13635 [handler.py:handle_request():146] handle_request: status_report
2025-02-26 22:13:15,211 DEBUG   HandlerThread:13635 [handler.py:handle_request():146] handle_request: keepalive
2025-02-26 22:13:15,435 DEBUG   HandlerThread:13635 [handler.py:handle_request():146] handle_request: status_report
2025-02-26 22:13:17,491 DEBUG   HandlerThread:13635 [handler.py:handle_request():146] handle_request: status_report
2025-02-26 22:13:20,227 DEBUG   HandlerThread:13635 [handler.py:handle_request():146] handle_request: keepalive
2025-02-26 22:13:20,455 DEBUG   HandlerThread:13635 [handler.py:handle_request():146] handle_request: status_report
2025-02-26 22:13:22,510 DEBUG   HandlerThread:13635 [handler.py:handle_request():146] handle_request: status_report
2025-02-26 22:13:25,249 DEBUG   HandlerThread:13635 [handler.py:handle_request():146] handle_request: keepalive
2025-02-26 22:13:25,478 DEBUG   HandlerThread:13635 [handler.py:handle_request():146] handle_request: status_report
2025-02-26 22:13:27,523 DEBUG   HandlerThread:13635 [handler.py:handle_request():146] handle_request: status_report
2025-02-26 22:13:30,271 DEBUG   HandlerThread:13635 [handler.py:handle_request():146] handle_request: keepalive
2025-02-26 22:13:30,497 DEBUG   HandlerThread:13635 [handler.py:handle_request():146] handle_request: status_report
2025-02-26 22:13:32,534 DEBUG   HandlerThread:13635 [handler.py:handle_request():146] handle_request: status_report
2025-02-26 22:13:35,293 DEBUG   HandlerThread:13635 [handler.py:handle_request():146] handle_request: keepalive
2025-02-26 22:13:35,518 DEBUG   HandlerThread:13635 [handler.py:handle_request():146] handle_request: status_report
2025-02-26 22:13:37,556 DEBUG   HandlerThread:13635 [handler.py:handle_request():146] handle_request: status_report
2025-02-26 22:13:40,314 DEBUG   HandlerThread:13635 [handler.py:handle_request():146] handle_request: keepalive
2025-02-26 22:13:40,530 DEBUG   HandlerThread:13635 [handler.py:handle_request():146] handle_request: status_report
2025-02-26 22:13:42,571 DEBUG   HandlerThread:13635 [handler.py:handle_request():146] handle_request: status_report
2025-02-26 22:13:45,321 DEBUG   HandlerThread:13635 [handler.py:handle_request():146] handle_request: keepalive
2025-02-26 22:13:45,534 DEBUG   HandlerThread:13635 [handler.py:handle_request():146] handle_request: status_report
2025-02-26 22:13:47,583 DEBUG   HandlerThread:13635 [handler.py:handle_request():146] handle_request: status_report
2025-02-26 22:13:50,335 DEBUG   HandlerThread:13635 [handler.py:handle_request():146] handle_request: keepalive
2025-02-26 22:13:50,540 DEBUG   HandlerThread:13635 [handler.py:handle_request():146] handle_request: status_report
2025-02-26 22:13:52,595 DEBUG   HandlerThread:13635 [handler.py:handle_request():146] handle_request: status_report
2025-02-26 22:13:55,346 DEBUG   HandlerThread:13635 [handler.py:handle_request():146] handle_request: keepalive
2025-02-26 22:13:55,553 DEBUG   HandlerThread:13635 [handler.py:handle_request():146] handle_request: status_report
2025-02-26 22:13:57,599 DEBUG   HandlerThread:13635 [handler.py:handle_request():146] handle_request: status_report
2025-02-26 22:14:00,361 DEBUG   HandlerThread:13635 [handler.py:handle_request():146] handle_request: keepalive
2025-02-26 22:14:00,567 DEBUG   HandlerThread:13635 [handler.py:handle_request():146] handle_request: status_report
2025-02-26 22:14:02,612 DEBUG   HandlerThread:13635 [handler.py:handle_request():146] handle_request: status_report
2025-02-26 22:14:05,380 DEBUG   HandlerThread:13635 [handler.py:handle_request():146] handle_request: keepalive
2025-02-26 22:14:05,586 DEBUG   HandlerThread:13635 [handler.py:handle_request():146] handle_request: status_report
2025-02-26 22:14:07,619 DEBUG   HandlerThread:13635 [handler.py:handle_request():146] handle_request: status_report
2025-02-26 22:14:10,396 DEBUG   HandlerThread:13635 [handler.py:handle_request():146] handle_request: keepalive
2025-02-26 22:14:10,601 DEBUG   HandlerThread:13635 [handler.py:handle_request():146] handle_request: status_report
2025-02-26 22:14:12,636 DEBUG   HandlerThread:13635 [handler.py:handle_request():146] handle_request: status_report
2025-02-26 22:14:15,418 DEBUG   HandlerThread:13635 [handler.py:handle_request():146] handle_request: keepalive
2025-02-26 22:14:15,617 DEBUG   HandlerThread:13635 [handler.py:handle_request():146] handle_request: status_report
2025-02-26 22:14:17,650 DEBUG   HandlerThread:13635 [handler.py:handle_request():146] handle_request: status_report
2025-02-26 22:14:20,436 DEBUG   HandlerThread:13635 [handler.py:handle_request():146] handle_request: keepalive
2025-02-26 22:14:20,635 DEBUG   HandlerThread:13635 [handler.py:handle_request():146] handle_request: status_report
2025-02-26 22:14:22,667 DEBUG   HandlerThread:13635 [handler.py:handle_request():146] handle_request: status_report
2025-02-26 22:14:25,457 DEBUG   HandlerThread:13635 [handler.py:handle_request():146] handle_request: keepalive
2025-02-26 22:14:25,652 DEBUG   HandlerThread:13635 [handler.py:handle_request():146] handle_request: status_report
2025-02-26 22:14:27,679 DEBUG   HandlerThread:13635 [handler.py:handle_request():146] handle_request: status_report
2025-02-26 22:14:30,465 DEBUG   HandlerThread:13635 [handler.py:handle_request():146] handle_request: cancel
2025-02-26 22:14:30,465 DEBUG   HandlerThread:13635 [handler.py:handle_request():146] handle_request: cancel
2025-02-26 22:14:30,666 DEBUG   HandlerThread:13635 [handler.py:handle_request():146] handle_request: status_report
2025-02-26 22:14:30,971 DEBUG   HandlerThread:13635 [handler.py:handle_request():146] handle_request: shutdown
2025-02-26 22:14:30,971 INFO    HandlerThread:13635 [handler.py:finish():866] shutting down handler
2025-02-26 22:14:31,695 INFO    SenderThread:13635 [sender.py:finish():1546] shutting down sender
2025-02-26 22:14:31,695 INFO    WriterThread:13635 [datastore.py:close():296] close: /Users/cpconnor/CascadeProjects/multi-platform-content-generator/wandb/run-20250226_221257-krq6o5ea/run-krq6o5ea.wandb
